[2025-08-05T22:26:41.852+0000] {local_task_job_runner.py:123} INFO - ::group::Pre task execution logs
[2025-08-05T22:26:41.864+0000] {taskinstance.py:2614} INFO - Dependencies all met for dep_context=non-requeueable deps ti=<TaskInstance: music_generator.generator_music_data manual__2025-08-05T22:26:40.844829+00:00 [queued]>
[2025-08-05T22:26:41.871+0000] {taskinstance.py:2614} INFO - Dependencies all met for dep_context=requeueable deps ti=<TaskInstance: music_generator.generator_music_data manual__2025-08-05T22:26:40.844829+00:00 [queued]>
[2025-08-05T22:26:41.872+0000] {taskinstance.py:2867} INFO - Starting attempt 1 of 1
[2025-08-05T22:26:41.877+0000] {taskinstance.py:2890} INFO - Executing <Task(MusicProduceOperator): generator_music_data> on 2025-08-05 22:26:40.844829+00:00
[2025-08-05T22:26:41.889+0000] {logging_mixin.py:190} WARNING - /home/***/.local/lib/python3.12/site-packages/***/task/task_runner/standard_task_runner.py:70 DeprecationWarning: This process (pid=2853) is multi-threaded, use of fork() may lead to deadlocks in the child.
[2025-08-05T22:26:41.890+0000] {standard_task_runner.py:72} INFO - Started process 2858 to run task
[2025-08-05T22:26:41.890+0000] {standard_task_runner.py:104} INFO - Running: ['***', 'tasks', 'run', 'music_generator', 'generator_music_data', 'manual__2025-08-05T22:26:40.844829+00:00', '--job-id', '768', '--raw', '--subdir', 'DAGS_FOLDER/music_generator.py', '--cfg-path', '/tmp/tmp3qyj65rq']
[2025-08-05T22:26:41.893+0000] {standard_task_runner.py:105} INFO - Job 768: Subtask generator_music_data
[2025-08-05T22:26:41.937+0000] {task_command.py:467} INFO - Running <TaskInstance: music_generator.generator_music_data manual__2025-08-05T22:26:40.844829+00:00 [running]> on host 86211193b7ee
[2025-08-05T22:26:42.008+0000] {taskinstance.py:3134} INFO - Exporting env vars: AIRFLOW_CTX_DAG_OWNER='GGCODE' AIRFLOW_CTX_DAG_ID='music_generator' AIRFLOW_CTX_TASK_ID='generator_music_data' AIRFLOW_CTX_EXECUTION_DATE='2025-08-05T22:26:40.844829+00:00' AIRFLOW_CTX_TRY_NUMBER='1' AIRFLOW_CTX_DAG_RUN_ID='manual__2025-08-05T22:26:40.844829+00:00'
[2025-08-05T22:26:42.009+0000] {taskinstance.py:732} INFO - ::endgroup::
[2025-08-05T22:26:42.168+0000] {conn.py:1516} WARNING - DNS lookup failed for kafka-broker-1:19092, exception was [Errno -2] Name or service not known. Is your advertised.listeners (called advertised.host.name before Kafka 9) correct and resolvable?
[2025-08-05T22:26:42.168+0000] {conn.py:323} ERROR - <BrokerConnection client_id=kafka-python-producer-1, node_id=bootstrap-0 host=kafka-broker-1:19092 <connecting> [unspecified None]>: DNS lookup failed for kafka-broker-1:19092 (0)
[2025-08-05T22:26:42.168+0000] {conn.py:945} ERROR - <BrokerConnection client_id=kafka-python-producer-1, node_id=bootstrap-0 host=kafka-broker-1:19092 <connecting> [unspecified None]>: Closing connection. KafkaConnectionError: DNS failure
[2025-08-05T22:26:42.168+0000] {client_async.py:1049} WARNING - No node available during check_version; sleeping 0.04 secs
[2025-08-05T22:26:42.211+0000] {conn.py:1516} WARNING - DNS lookup failed for kafka-broker-1:19092, exception was [Errno -2] Name or service not known. Is your advertised.listeners (called advertised.host.name before Kafka 9) correct and resolvable?
[2025-08-05T22:26:42.211+0000] {conn.py:323} ERROR - <BrokerConnection client_id=kafka-python-producer-1, node_id=bootstrap-0 host=kafka-broker-1:19092 <connecting> [unspecified None]>: DNS lookup failed for kafka-broker-1:19092 (0)
[2025-08-05T22:26:42.211+0000] {conn.py:945} ERROR - <BrokerConnection client_id=kafka-python-producer-1, node_id=bootstrap-0 host=kafka-broker-1:19092 <connecting> [unspecified None]>: Closing connection. KafkaConnectionError: DNS failure
[2025-08-05T22:26:42.211+0000] {client_async.py:1049} WARNING - No node available during check_version; sleeping 0.11 secs
[2025-08-05T22:26:42.324+0000] {conn.py:1516} WARNING - DNS lookup failed for kafka-broker-1:19092, exception was [Errno -2] Name or service not known. Is your advertised.listeners (called advertised.host.name before Kafka 9) correct and resolvable?
[2025-08-05T22:26:42.324+0000] {conn.py:323} ERROR - <BrokerConnection client_id=kafka-python-producer-1, node_id=bootstrap-0 host=kafka-broker-1:19092 <connecting> [unspecified None]>: DNS lookup failed for kafka-broker-1:19092 (0)
[2025-08-05T22:26:42.324+0000] {conn.py:945} ERROR - <BrokerConnection client_id=kafka-python-producer-1, node_id=bootstrap-0 host=kafka-broker-1:19092 <connecting> [unspecified None]>: Closing connection. KafkaConnectionError: DNS failure
[2025-08-05T22:26:42.324+0000] {client_async.py:1049} WARNING - No node available during check_version; sleeping 0.21 secs
[2025-08-05T22:26:42.537+0000] {conn.py:1516} WARNING - DNS lookup failed for kafka-broker-1:19092, exception was [Errno -2] Name or service not known. Is your advertised.listeners (called advertised.host.name before Kafka 9) correct and resolvable?
[2025-08-05T22:26:42.537+0000] {conn.py:323} ERROR - <BrokerConnection client_id=kafka-python-producer-1, node_id=bootstrap-0 host=kafka-broker-1:19092 <connecting> [unspecified None]>: DNS lookup failed for kafka-broker-1:19092 (0)
[2025-08-05T22:26:42.538+0000] {conn.py:945} ERROR - <BrokerConnection client_id=kafka-python-producer-1, node_id=bootstrap-0 host=kafka-broker-1:19092 <connecting> [unspecified None]>: Closing connection. KafkaConnectionError: DNS failure
[2025-08-05T22:26:42.538+0000] {client_async.py:1049} WARNING - No node available during check_version; sleeping 0.43 secs
[2025-08-05T22:26:42.970+0000] {conn.py:1516} WARNING - DNS lookup failed for kafka-broker-1:19092, exception was [Errno -2] Name or service not known. Is your advertised.listeners (called advertised.host.name before Kafka 9) correct and resolvable?
[2025-08-05T22:26:42.971+0000] {conn.py:323} ERROR - <BrokerConnection client_id=kafka-python-producer-1, node_id=bootstrap-0 host=kafka-broker-1:19092 <connecting> [unspecified None]>: DNS lookup failed for kafka-broker-1:19092 (0)
[2025-08-05T22:26:42.971+0000] {conn.py:945} ERROR - <BrokerConnection client_id=kafka-python-producer-1, node_id=bootstrap-0 host=kafka-broker-1:19092 <connecting> [unspecified None]>: Closing connection. KafkaConnectionError: DNS failure
[2025-08-05T22:26:42.971+0000] {client_async.py:1049} WARNING - No node available during check_version; sleeping 0.79 secs
[2025-08-05T22:26:43.763+0000] {conn.py:1516} WARNING - DNS lookup failed for kafka-broker-1:19092, exception was [Errno -2] Name or service not known. Is your advertised.listeners (called advertised.host.name before Kafka 9) correct and resolvable?
[2025-08-05T22:26:43.764+0000] {conn.py:323} ERROR - <BrokerConnection client_id=kafka-python-producer-1, node_id=bootstrap-0 host=kafka-broker-1:19092 <connecting> [unspecified None]>: DNS lookup failed for kafka-broker-1:19092 (0)
[2025-08-05T22:26:43.764+0000] {conn.py:945} ERROR - <BrokerConnection client_id=kafka-python-producer-1, node_id=bootstrap-0 host=kafka-broker-1:19092 <connecting> [unspecified None]>: Closing connection. KafkaConnectionError: DNS failure
[2025-08-05T22:26:43.764+0000] {client_async.py:1049} WARNING - No node available during check_version; sleeping 0.40 secs
[2025-08-05T22:26:44.165+0000] {taskinstance.py:3313} ERROR - Task failed with exception
Traceback (most recent call last):
  File "/home/airflow/.local/lib/python3.12/site-packages/airflow/models/taskinstance.py", line 768, in _execute_task
    result = _execute_callable(context=context, **execute_callable_kwargs)
             ^^^^^^^^^^^^^^^^^^^^^^^^^^^^^^^^^^^^^^^^^^^^^^^^^^^^^^^^^^^^^
  File "/home/airflow/.local/lib/python3.12/site-packages/airflow/models/taskinstance.py", line 734, in _execute_callable
    return ExecutionCallableRunner(
           ^^^^^^^^^^^^^^^^^^^^^^^^
  File "/home/airflow/.local/lib/python3.12/site-packages/airflow/utils/operator_helpers.py", line 252, in run
    return self.func(*args, **kwargs)
           ^^^^^^^^^^^^^^^^^^^^^^^^^^
  File "/home/airflow/.local/lib/python3.12/site-packages/airflow/models/baseoperator.py", line 424, in wrapper
    return func(self, *args, **kwargs)
           ^^^^^^^^^^^^^^^^^^^^^^^^^^^
  File "/opt/airflow/plugins/music_kafka_operator.py", line 49, in execute
    producer = KafkaProducer(
               ^^^^^^^^^^^^^^
  File "/home/airflow/.local/lib/python3.12/site-packages/kafka/producer/kafka.py", line 481, in __init__
    client = self.config['kafka_client'](
             ^^^^^^^^^^^^^^^^^^^^^^^^^^^^
  File "/home/airflow/.local/lib/python3.12/site-packages/kafka/client_async.py", line 262, in __init__
    self.config['api_version'] = self.check_version()
                                 ^^^^^^^^^^^^^^^^^^^^
  File "/home/airflow/.local/lib/python3.12/site-packages/kafka/client_async.py", line 1074, in check_version
    raise Errors.NoBrokersAvailable()
kafka.errors.NoBrokersAvailable: NoBrokersAvailable
[2025-08-05T22:26:44.172+0000] {taskinstance.py:1226} INFO - Marking task as FAILED. dag_id=music_generator, task_id=generator_music_data, run_id=manual__2025-08-05T22:26:40.844829+00:00, execution_date=20250805T222640, start_date=20250805T222641, end_date=20250805T222644
[2025-08-05T22:26:44.180+0000] {taskinstance.py:341} INFO - ::group::Post task execution logs
[2025-08-05T22:26:44.180+0000] {standard_task_runner.py:124} ERROR - Failed to execute job 768 for task generator_music_data (NoBrokersAvailable; 2858)
Traceback (most recent call last):
  File "/home/airflow/.local/lib/python3.12/site-packages/airflow/task/task_runner/standard_task_runner.py", line 117, in _start_by_fork
    ret = args.func(args, dag=self.dag)
          ^^^^^^^^^^^^^^^^^^^^^^^^^^^^^
  File "/home/airflow/.local/lib/python3.12/site-packages/airflow/cli/cli_config.py", line 49, in command
    return func(*args, **kwargs)
           ^^^^^^^^^^^^^^^^^^^^^
  File "/home/airflow/.local/lib/python3.12/site-packages/airflow/utils/cli.py", line 116, in wrapper
    return f(*args, **kwargs)
           ^^^^^^^^^^^^^^^^^^
  File "/home/airflow/.local/lib/python3.12/site-packages/airflow/cli/commands/task_command.py", line 483, in task_run
    task_return_code = _run_task_by_selected_method(args, _dag, ti)
                       ^^^^^^^^^^^^^^^^^^^^^^^^^^^^^^^^^^^^^^^^^^^^
  File "/home/airflow/.local/lib/python3.12/site-packages/airflow/cli/commands/task_command.py", line 256, in _run_task_by_selected_method
    return _run_raw_task(args, ti)
           ^^^^^^^^^^^^^^^^^^^^^^^
  File "/home/airflow/.local/lib/python3.12/site-packages/airflow/cli/commands/task_command.py", line 341, in _run_raw_task
    return ti._run_raw_task(
           ^^^^^^^^^^^^^^^^^
  File "/home/airflow/.local/lib/python3.12/site-packages/airflow/utils/session.py", line 97, in wrapper
    return func(*args, session=session, **kwargs)
           ^^^^^^^^^^^^^^^^^^^^^^^^^^^^^^^^^^^^^^
  File "/home/airflow/.local/lib/python3.12/site-packages/airflow/models/taskinstance.py", line 3006, in _run_raw_task
    return _run_raw_task(
           ^^^^^^^^^^^^^^
  File "/home/airflow/.local/lib/python3.12/site-packages/airflow/models/taskinstance.py", line 274, in _run_raw_task
    TaskInstance._execute_task_with_callbacks(
  File "/home/airflow/.local/lib/python3.12/site-packages/airflow/models/taskinstance.py", line 3161, in _execute_task_with_callbacks
    result = self._execute_task(context, task_orig)
             ^^^^^^^^^^^^^^^^^^^^^^^^^^^^^^^^^^^^^^
  File "/home/airflow/.local/lib/python3.12/site-packages/airflow/models/taskinstance.py", line 3185, in _execute_task
    return _execute_task(self, context, task_orig)
           ^^^^^^^^^^^^^^^^^^^^^^^^^^^^^^^^^^^^^^^
  File "/home/airflow/.local/lib/python3.12/site-packages/airflow/models/taskinstance.py", line 768, in _execute_task
    result = _execute_callable(context=context, **execute_callable_kwargs)
             ^^^^^^^^^^^^^^^^^^^^^^^^^^^^^^^^^^^^^^^^^^^^^^^^^^^^^^^^^^^^^
  File "/home/airflow/.local/lib/python3.12/site-packages/airflow/models/taskinstance.py", line 734, in _execute_callable
    return ExecutionCallableRunner(
           ^^^^^^^^^^^^^^^^^^^^^^^^
  File "/home/airflow/.local/lib/python3.12/site-packages/airflow/utils/operator_helpers.py", line 252, in run
    return self.func(*args, **kwargs)
           ^^^^^^^^^^^^^^^^^^^^^^^^^^
  File "/home/airflow/.local/lib/python3.12/site-packages/airflow/models/baseoperator.py", line 424, in wrapper
    return func(self, *args, **kwargs)
           ^^^^^^^^^^^^^^^^^^^^^^^^^^^
  File "/opt/airflow/plugins/music_kafka_operator.py", line 49, in execute
    producer = KafkaProducer(
               ^^^^^^^^^^^^^^
  File "/home/airflow/.local/lib/python3.12/site-packages/kafka/producer/kafka.py", line 481, in __init__
    client = self.config['kafka_client'](
             ^^^^^^^^^^^^^^^^^^^^^^^^^^^^
  File "/home/airflow/.local/lib/python3.12/site-packages/kafka/client_async.py", line 262, in __init__
    self.config['api_version'] = self.check_version()
                                 ^^^^^^^^^^^^^^^^^^^^
  File "/home/airflow/.local/lib/python3.12/site-packages/kafka/client_async.py", line 1074, in check_version
    raise Errors.NoBrokersAvailable()
kafka.errors.NoBrokersAvailable: NoBrokersAvailable
[2025-08-05T22:26:44.209+0000] {local_task_job_runner.py:266} INFO - Task exited with return code 1
[2025-08-05T22:26:44.219+0000] {taskinstance.py:3901} INFO - 0 downstream tasks scheduled from follow-on schedule check
[2025-08-05T22:26:44.220+0000] {local_task_job_runner.py:245} INFO - ::endgroup::
