[2025-08-04T21:50:36.144+0000] {local_task_job_runner.py:123} INFO - ::group::Pre task execution logs
[2025-08-04T21:50:36.187+0000] {taskinstance.py:2614} INFO - Dependencies all met for dep_context=non-requeueable deps ti=<TaskInstance: artist_generator.generator_artist_data scheduled__2025-01-08T00:00:00+00:00 [queued]>
[2025-08-04T21:50:36.199+0000] {taskinstance.py:2614} INFO - Dependencies all met for dep_context=requeueable deps ti=<TaskInstance: artist_generator.generator_artist_data scheduled__2025-01-08T00:00:00+00:00 [queued]>
[2025-08-04T21:50:36.201+0000] {taskinstance.py:2867} INFO - Starting attempt 1 of 1
[2025-08-04T21:50:36.339+0000] {taskinstance.py:2890} INFO - Executing <Task(ArtistProduceOperator): generator_artist_data> on 2025-01-08 00:00:00+00:00
[2025-08-04T21:50:36.361+0000] {logging_mixin.py:190} WARNING - /home/***/.local/lib/python3.12/site-packages/***/task/task_runner/standard_task_runner.py:70 DeprecationWarning: This process (pid=7193) is multi-threaded, use of fork() may lead to deadlocks in the child.
[2025-08-04T21:50:36.365+0000] {standard_task_runner.py:72} INFO - Started process 7228 to run task
[2025-08-04T21:50:36.369+0000] {standard_task_runner.py:104} INFO - Running: ['***', 'tasks', 'run', 'artist_generator', 'generator_artist_data', 'scheduled__2025-01-08T00:00:00+00:00', '--job-id', '239', '--raw', '--subdir', 'DAGS_FOLDER/artist_generator.py', '--cfg-path', '/tmp/tmp5s67r6r2']
[2025-08-04T21:50:36.391+0000] {standard_task_runner.py:105} INFO - Job 239: Subtask generator_artist_data
[2025-08-04T21:50:36.521+0000] {task_command.py:467} INFO - Running <TaskInstance: artist_generator.generator_artist_data scheduled__2025-01-08T00:00:00+00:00 [running]> on host c4e4284cebf8
[2025-08-04T21:50:36.605+0000] {taskinstance.py:3134} INFO - Exporting env vars: AIRFLOW_CTX_DAG_OWNER='GGCODE' AIRFLOW_CTX_DAG_ID='artist_generator' AIRFLOW_CTX_TASK_ID='generator_artist_data' AIRFLOW_CTX_EXECUTION_DATE='2025-01-08T00:00:00+00:00' AIRFLOW_CTX_TRY_NUMBER='1' AIRFLOW_CTX_DAG_RUN_ID='scheduled__2025-01-08T00:00:00+00:00'
[2025-08-04T21:50:36.607+0000] {taskinstance.py:732} INFO - ::endgroup::
[2025-08-04T21:50:36.640+0000] {conn.py:396} INFO - <BrokerConnection client_id=kafka-python-producer-1, node_id=bootstrap-0 host=kafka-broker-1:19092 <connecting> [IPv4 ('172.18.0.9', 19092)]>: connecting to kafka-broker-1:19092 [('172.18.0.9', 19092) IPv4]
[2025-08-04T21:50:36.652+0000] {conn.py:618} INFO - <BrokerConnection client_id=kafka-python-producer-1, node_id=bootstrap-0 host=kafka-broker-1:19092 <checking_api_versions_recv> [IPv4 ('172.18.0.9', 19092)]>: Broker version identified as 2.6
[2025-08-04T21:50:36.653+0000] {conn.py:457} INFO - <BrokerConnection client_id=kafka-python-producer-1, node_id=bootstrap-0 host=kafka-broker-1:19092 <connected> [IPv4 ('172.18.0.9', 19092)]>: Connection complete.
[2025-08-04T21:50:38.201+0000] {conn.py:1516} WARNING - DNS lookup failed for kafka-broker-3:19092, exception was [Errno -2] Name or service not known. Is your advertised.listeners (called advertised.host.name before Kafka 9) correct and resolvable?
[2025-08-04T21:50:38.213+0000] {conn.py:323} ERROR - <BrokerConnection client_id=kafka-python-producer-1, node_id=6 host=kafka-broker-3:19092 <connecting> [unspecified None]>: DNS lookup failed for kafka-broker-3:19092 (0)
[2025-08-04T21:50:38.214+0000] {conn.py:945} ERROR - <BrokerConnection client_id=kafka-python-producer-1, node_id=6 host=kafka-broker-3:19092 <connecting> [unspecified None]>: Closing connection. KafkaConnectionError: DNS failure
[2025-08-04T21:50:38.215+0000] {client_async.py:388} WARNING - Node 6 connection failed -- refreshing metadata
[2025-08-04T21:50:38.271+0000] {conn.py:1516} WARNING - DNS lookup failed for kafka-broker-3:19092, exception was [Errno -2] Name or service not known. Is your advertised.listeners (called advertised.host.name before Kafka 9) correct and resolvable?
[2025-08-04T21:50:38.277+0000] {conn.py:323} ERROR - <BrokerConnection client_id=kafka-python-producer-1, node_id=6 host=kafka-broker-3:19092 <connecting> [unspecified None]>: DNS lookup failed for kafka-broker-3:19092 (0)
[2025-08-04T21:50:38.285+0000] {conn.py:945} ERROR - <BrokerConnection client_id=kafka-python-producer-1, node_id=6 host=kafka-broker-3:19092 <connecting> [unspecified None]>: Closing connection. KafkaConnectionError: DNS failure
[2025-08-04T21:50:38.288+0000] {client_async.py:388} WARNING - Node 6 connection failed -- refreshing metadata
[2025-08-04T21:50:38.293+0000] {conn.py:945} ERROR - <BrokerConnection client_id=kafka-python-producer-1, node_id=bootstrap-0 host=kafka-broker-1:19092 <connected> [IPv4 ('172.18.0.9', 19092)]>: Closing connection. KafkaConnectionError: Socket EVENT_READ without in-flight-requests
[2025-08-04T21:50:38.297+0000] {conn.py:396} INFO - <BrokerConnection client_id=kafka-python-producer-1, node_id=4 host=kafka-broker-1:19092 <connecting> [IPv4 ('172.18.0.9', 19092)]>: connecting to kafka-broker-1:19092 [('172.18.0.9', 19092) IPv4]
[2025-08-04T21:50:38.298+0000] {conn.py:429} ERROR - <BrokerConnection client_id=kafka-python-producer-1, node_id=4 host=kafka-broker-1:19092 <connecting> [IPv4 ('172.18.0.9', 19092)]>: Connect attempt returned error 111. Disconnecting.
[2025-08-04T21:50:38.300+0000] {conn.py:945} ERROR - <BrokerConnection client_id=kafka-python-producer-1, node_id=4 host=kafka-broker-1:19092 <connecting> [IPv4 ('172.18.0.9', 19092)]>: Closing connection. KafkaConnectionError: 111 ECONNREFUSED
[2025-08-04T21:50:38.302+0000] {client_async.py:388} WARNING - Node 4 connection failed -- refreshing metadata
[2025-08-04T21:50:38.314+0000] {conn.py:1516} WARNING - DNS lookup failed for kafka-broker-2:19092, exception was [Errno -2] Name or service not known. Is your advertised.listeners (called advertised.host.name before Kafka 9) correct and resolvable?
[2025-08-04T21:50:38.315+0000] {conn.py:323} ERROR - <BrokerConnection client_id=kafka-python-producer-1, node_id=5 host=kafka-broker-2:19092 <connecting> [unspecified None]>: DNS lookup failed for kafka-broker-2:19092 (0)
[2025-08-04T21:50:38.319+0000] {conn.py:945} ERROR - <BrokerConnection client_id=kafka-python-producer-1, node_id=5 host=kafka-broker-2:19092 <connecting> [unspecified None]>: Closing connection. KafkaConnectionError: DNS failure
[2025-08-04T21:50:38.320+0000] {client_async.py:388} WARNING - Node 5 connection failed -- refreshing metadata
[2025-08-04T21:50:38.371+0000] {conn.py:396} INFO - <BrokerConnection client_id=kafka-python-producer-1, node_id=4 host=kafka-broker-1:19092 <connecting> [IPv4 ('172.18.0.9', 19092)]>: connecting to kafka-broker-1:19092 [('172.18.0.9', 19092) IPv4]
[2025-08-04T21:50:38.376+0000] {conn.py:429} ERROR - <BrokerConnection client_id=kafka-python-producer-1, node_id=4 host=kafka-broker-1:19092 <connecting> [IPv4 ('172.18.0.9', 19092)]>: Connect attempt returned error 111. Disconnecting.
[2025-08-04T21:50:38.377+0000] {conn.py:945} ERROR - <BrokerConnection client_id=kafka-python-producer-1, node_id=4 host=kafka-broker-1:19092 <connecting> [IPv4 ('172.18.0.9', 19092)]>: Closing connection. KafkaConnectionError: 111 ECONNREFUSED
[2025-08-04T21:50:38.377+0000] {client_async.py:388} WARNING - Node 4 connection failed -- refreshing metadata
[2025-08-04T21:50:38.391+0000] {conn.py:1516} WARNING - DNS lookup failed for kafka-broker-3:19092, exception was [Errno -2] Name or service not known. Is your advertised.listeners (called advertised.host.name before Kafka 9) correct and resolvable?
[2025-08-04T21:50:38.398+0000] {conn.py:323} ERROR - <BrokerConnection client_id=kafka-python-producer-1, node_id=6 host=kafka-broker-3:19092 <connecting> [unspecified None]>: DNS lookup failed for kafka-broker-3:19092 (0)
[2025-08-04T21:50:38.401+0000] {conn.py:945} ERROR - <BrokerConnection client_id=kafka-python-producer-1, node_id=6 host=kafka-broker-3:19092 <connecting> [unspecified None]>: Closing connection. KafkaConnectionError: DNS failure
[2025-08-04T21:50:38.405+0000] {client_async.py:388} WARNING - Node 6 connection failed -- refreshing metadata
[2025-08-04T21:50:38.475+0000] {conn.py:396} INFO - <BrokerConnection client_id=kafka-python-producer-1, node_id=4 host=kafka-broker-1:19092 <connecting> [IPv4 ('172.18.0.9', 19092)]>: connecting to kafka-broker-1:19092 [('172.18.0.9', 19092) IPv4]
[2025-08-04T21:50:38.482+0000] {conn.py:429} ERROR - <BrokerConnection client_id=kafka-python-producer-1, node_id=4 host=kafka-broker-1:19092 <connecting> [IPv4 ('172.18.0.9', 19092)]>: Connect attempt returned error 111. Disconnecting.
[2025-08-04T21:50:38.486+0000] {conn.py:945} ERROR - <BrokerConnection client_id=kafka-python-producer-1, node_id=4 host=kafka-broker-1:19092 <connecting> [IPv4 ('172.18.0.9', 19092)]>: Closing connection. KafkaConnectionError: 111 ECONNREFUSED
[2025-08-04T21:50:38.487+0000] {client_async.py:388} WARNING - Node 4 connection failed -- refreshing metadata
[2025-08-04T21:50:38.491+0000] {conn.py:1516} WARNING - DNS lookup failed for kafka-broker-2:19092, exception was [Errno -2] Name or service not known. Is your advertised.listeners (called advertised.host.name before Kafka 9) correct and resolvable?
[2025-08-04T21:50:38.492+0000] {conn.py:323} ERROR - <BrokerConnection client_id=kafka-python-producer-1, node_id=5 host=kafka-broker-2:19092 <connecting> [unspecified None]>: DNS lookup failed for kafka-broker-2:19092 (0)
[2025-08-04T21:50:38.493+0000] {conn.py:945} ERROR - <BrokerConnection client_id=kafka-python-producer-1, node_id=5 host=kafka-broker-2:19092 <connecting> [unspecified None]>: Closing connection. KafkaConnectionError: DNS failure
[2025-08-04T21:50:38.499+0000] {client_async.py:388} WARNING - Node 5 connection failed -- refreshing metadata
[2025-08-04T21:50:38.586+0000] {conn.py:1516} WARNING - DNS lookup failed for kafka-broker-2:19092, exception was [Errno -2] Name or service not known. Is your advertised.listeners (called advertised.host.name before Kafka 9) correct and resolvable?
[2025-08-04T21:50:38.587+0000] {conn.py:323} ERROR - <BrokerConnection client_id=kafka-python-producer-1, node_id=5 host=kafka-broker-2:19092 <connecting> [unspecified None]>: DNS lookup failed for kafka-broker-2:19092 (0)
[2025-08-04T21:50:38.587+0000] {conn.py:945} ERROR - <BrokerConnection client_id=kafka-python-producer-1, node_id=5 host=kafka-broker-2:19092 <connecting> [unspecified None]>: Closing connection. KafkaConnectionError: DNS failure
[2025-08-04T21:50:38.588+0000] {client_async.py:388} WARNING - Node 5 connection failed -- refreshing metadata
[2025-08-04T21:50:38.645+0000] {conn.py:1516} WARNING - DNS lookup failed for kafka-broker-3:19092, exception was [Errno -2] Name or service not known. Is your advertised.listeners (called advertised.host.name before Kafka 9) correct and resolvable?
[2025-08-04T21:50:38.650+0000] {conn.py:323} ERROR - <BrokerConnection client_id=kafka-python-producer-1, node_id=6 host=kafka-broker-3:19092 <connecting> [unspecified None]>: DNS lookup failed for kafka-broker-3:19092 (0)
[2025-08-04T21:50:38.653+0000] {conn.py:945} ERROR - <BrokerConnection client_id=kafka-python-producer-1, node_id=6 host=kafka-broker-3:19092 <connecting> [unspecified None]>: Closing connection. KafkaConnectionError: DNS failure
[2025-08-04T21:50:38.657+0000] {client_async.py:388} WARNING - Node 6 connection failed -- refreshing metadata
[2025-08-04T21:50:38.732+0000] {conn.py:1516} WARNING - DNS lookup failed for kafka-broker-1:19092, exception was [Errno -2] Name or service not known. Is your advertised.listeners (called advertised.host.name before Kafka 9) correct and resolvable?
[2025-08-04T21:50:38.733+0000] {conn.py:323} ERROR - <BrokerConnection client_id=kafka-python-producer-1, node_id=4 host=kafka-broker-1:19092 <connecting> [IPv4 ('172.18.0.9', 19092)]>: DNS lookup failed for kafka-broker-1:19092 (0)
[2025-08-04T21:50:38.733+0000] {conn.py:945} ERROR - <BrokerConnection client_id=kafka-python-producer-1, node_id=4 host=kafka-broker-1:19092 <connecting> [IPv4 ('172.18.0.9', 19092)]>: Closing connection. KafkaConnectionError: DNS failure
[2025-08-04T21:50:38.734+0000] {client_async.py:388} WARNING - Node 4 connection failed -- refreshing metadata
[2025-08-04T21:50:38.837+0000] {conn.py:1516} WARNING - DNS lookup failed for kafka-broker-2:19092, exception was [Errno -2] Name or service not known. Is your advertised.listeners (called advertised.host.name before Kafka 9) correct and resolvable?
[2025-08-04T21:50:38.852+0000] {conn.py:323} ERROR - <BrokerConnection client_id=kafka-python-producer-1, node_id=5 host=kafka-broker-2:19092 <connecting> [unspecified None]>: DNS lookup failed for kafka-broker-2:19092 (0)
[2025-08-04T21:50:38.854+0000] {conn.py:945} ERROR - <BrokerConnection client_id=kafka-python-producer-1, node_id=5 host=kafka-broker-2:19092 <connecting> [unspecified None]>: Closing connection. KafkaConnectionError: DNS failure
[2025-08-04T21:50:38.858+0000] {client_async.py:388} WARNING - Node 5 connection failed -- refreshing metadata
[2025-08-04T21:50:39.128+0000] {conn.py:1516} WARNING - DNS lookup failed for kafka-broker-3:19092, exception was [Errno -2] Name or service not known. Is your advertised.listeners (called advertised.host.name before Kafka 9) correct and resolvable?
[2025-08-04T21:50:39.131+0000] {conn.py:323} ERROR - <BrokerConnection client_id=kafka-python-producer-1, node_id=6 host=kafka-broker-3:19092 <connecting> [unspecified None]>: DNS lookup failed for kafka-broker-3:19092 (0)
[2025-08-04T21:50:39.135+0000] {conn.py:945} ERROR - <BrokerConnection client_id=kafka-python-producer-1, node_id=6 host=kafka-broker-3:19092 <connecting> [unspecified None]>: Closing connection. KafkaConnectionError: DNS failure
[2025-08-04T21:50:39.139+0000] {client_async.py:388} WARNING - Node 6 connection failed -- refreshing metadata
[2025-08-04T21:50:39.203+0000] {conn.py:1516} WARNING - DNS lookup failed for kafka-broker-1:19092, exception was [Errno -2] Name or service not known. Is your advertised.listeners (called advertised.host.name before Kafka 9) correct and resolvable?
[2025-08-04T21:50:39.205+0000] {conn.py:323} ERROR - <BrokerConnection client_id=kafka-python-producer-1, node_id=4 host=kafka-broker-1:19092 <connecting> [IPv4 ('172.18.0.9', 19092)]>: DNS lookup failed for kafka-broker-1:19092 (0)
[2025-08-04T21:50:39.206+0000] {conn.py:945} ERROR - <BrokerConnection client_id=kafka-python-producer-1, node_id=4 host=kafka-broker-1:19092 <connecting> [IPv4 ('172.18.0.9', 19092)]>: Closing connection. KafkaConnectionError: DNS failure
[2025-08-04T21:50:39.209+0000] {client_async.py:388} WARNING - Node 4 connection failed -- refreshing metadata
[2025-08-04T21:50:39.269+0000] {conn.py:1516} WARNING - DNS lookup failed for kafka-broker-2:19092, exception was [Errno -2] Name or service not known. Is your advertised.listeners (called advertised.host.name before Kafka 9) correct and resolvable?
[2025-08-04T21:50:39.270+0000] {conn.py:323} ERROR - <BrokerConnection client_id=kafka-python-producer-1, node_id=5 host=kafka-broker-2:19092 <connecting> [unspecified None]>: DNS lookup failed for kafka-broker-2:19092 (0)
[2025-08-04T21:50:39.271+0000] {conn.py:945} ERROR - <BrokerConnection client_id=kafka-python-producer-1, node_id=5 host=kafka-broker-2:19092 <connecting> [unspecified None]>: Closing connection. KafkaConnectionError: DNS failure
[2025-08-04T21:50:39.275+0000] {client_async.py:388} WARNING - Node 5 connection failed -- refreshing metadata
[2025-08-04T21:50:39.955+0000] {conn.py:1516} WARNING - DNS lookup failed for kafka-broker-3:19092, exception was [Errno -2] Name or service not known. Is your advertised.listeners (called advertised.host.name before Kafka 9) correct and resolvable?
[2025-08-04T21:50:39.955+0000] {conn.py:323} ERROR - <BrokerConnection client_id=kafka-python-producer-1, node_id=6 host=kafka-broker-3:19092 <connecting> [unspecified None]>: DNS lookup failed for kafka-broker-3:19092 (0)
[2025-08-04T21:50:39.955+0000] {conn.py:945} ERROR - <BrokerConnection client_id=kafka-python-producer-1, node_id=6 host=kafka-broker-3:19092 <connecting> [unspecified None]>: Closing connection. KafkaConnectionError: DNS failure
[2025-08-04T21:50:39.955+0000] {client_async.py:388} WARNING - Node 6 connection failed -- refreshing metadata
[2025-08-04T21:50:40.009+0000] {conn.py:1516} WARNING - DNS lookup failed for kafka-broker-1:19092, exception was [Errno -2] Name or service not known. Is your advertised.listeners (called advertised.host.name before Kafka 9) correct and resolvable?
[2025-08-04T21:50:40.009+0000] {conn.py:323} ERROR - <BrokerConnection client_id=kafka-python-producer-1, node_id=4 host=kafka-broker-1:19092 <connecting> [IPv4 ('172.18.0.9', 19092)]>: DNS lookup failed for kafka-broker-1:19092 (0)
[2025-08-04T21:50:40.009+0000] {conn.py:945} ERROR - <BrokerConnection client_id=kafka-python-producer-1, node_id=4 host=kafka-broker-1:19092 <connecting> [IPv4 ('172.18.0.9', 19092)]>: Closing connection. KafkaConnectionError: DNS failure
[2025-08-04T21:50:40.009+0000] {client_async.py:388} WARNING - Node 4 connection failed -- refreshing metadata
[2025-08-04T21:50:40.188+0000] {conn.py:1516} WARNING - DNS lookup failed for kafka-broker-2:19092, exception was [Errno -2] Name or service not known. Is your advertised.listeners (called advertised.host.name before Kafka 9) correct and resolvable?
[2025-08-04T21:50:40.189+0000] {conn.py:323} ERROR - <BrokerConnection client_id=kafka-python-producer-1, node_id=5 host=kafka-broker-2:19092 <connecting> [unspecified None]>: DNS lookup failed for kafka-broker-2:19092 (0)
[2025-08-04T21:50:40.189+0000] {conn.py:945} ERROR - <BrokerConnection client_id=kafka-python-producer-1, node_id=5 host=kafka-broker-2:19092 <connecting> [unspecified None]>: Closing connection. KafkaConnectionError: DNS failure
[2025-08-04T21:50:40.189+0000] {client_async.py:388} WARNING - Node 5 connection failed -- refreshing metadata
[2025-08-04T21:50:41.387+0000] {conn.py:1516} WARNING - DNS lookup failed for kafka-broker-3:19092, exception was [Errno -2] Name or service not known. Is your advertised.listeners (called advertised.host.name before Kafka 9) correct and resolvable?
[2025-08-04T21:50:41.388+0000] {conn.py:323} ERROR - <BrokerConnection client_id=kafka-python-producer-1, node_id=6 host=kafka-broker-3:19092 <connecting> [unspecified None]>: DNS lookup failed for kafka-broker-3:19092 (0)
[2025-08-04T21:50:41.388+0000] {conn.py:945} ERROR - <BrokerConnection client_id=kafka-python-producer-1, node_id=6 host=kafka-broker-3:19092 <connecting> [unspecified None]>: Closing connection. KafkaConnectionError: DNS failure
[2025-08-04T21:50:41.389+0000] {client_async.py:388} WARNING - Node 6 connection failed -- refreshing metadata
[2025-08-04T21:50:41.678+0000] {conn.py:1516} WARNING - DNS lookup failed for kafka-broker-2:19092, exception was [Errno -2] Name or service not known. Is your advertised.listeners (called advertised.host.name before Kafka 9) correct and resolvable?
[2025-08-04T21:50:41.679+0000] {conn.py:323} ERROR - <BrokerConnection client_id=kafka-python-producer-1, node_id=5 host=kafka-broker-2:19092 <connecting> [unspecified None]>: DNS lookup failed for kafka-broker-2:19092 (0)
[2025-08-04T21:50:41.679+0000] {conn.py:945} ERROR - <BrokerConnection client_id=kafka-python-producer-1, node_id=5 host=kafka-broker-2:19092 <connecting> [unspecified None]>: Closing connection. KafkaConnectionError: DNS failure
[2025-08-04T21:50:41.680+0000] {client_async.py:388} WARNING - Node 5 connection failed -- refreshing metadata
[2025-08-04T21:50:41.817+0000] {conn.py:1516} WARNING - DNS lookup failed for kafka-broker-1:19092, exception was [Errno -2] Name or service not known. Is your advertised.listeners (called advertised.host.name before Kafka 9) correct and resolvable?
[2025-08-04T21:50:41.817+0000] {conn.py:323} ERROR - <BrokerConnection client_id=kafka-python-producer-1, node_id=4 host=kafka-broker-1:19092 <connecting> [IPv4 ('172.18.0.9', 19092)]>: DNS lookup failed for kafka-broker-1:19092 (0)
[2025-08-04T21:50:41.817+0000] {conn.py:945} ERROR - <BrokerConnection client_id=kafka-python-producer-1, node_id=4 host=kafka-broker-1:19092 <connecting> [IPv4 ('172.18.0.9', 19092)]>: Closing connection. KafkaConnectionError: DNS failure
[2025-08-04T21:50:41.817+0000] {client_async.py:388} WARNING - Node 4 connection failed -- refreshing metadata
[2025-08-04T21:50:44.971+0000] {conn.py:1516} WARNING - DNS lookup failed for kafka-broker-2:19092, exception was [Errno -2] Name or service not known. Is your advertised.listeners (called advertised.host.name before Kafka 9) correct and resolvable?
[2025-08-04T21:50:44.972+0000] {conn.py:323} ERROR - <BrokerConnection client_id=kafka-python-producer-1, node_id=5 host=kafka-broker-2:19092 <connecting> [unspecified None]>: DNS lookup failed for kafka-broker-2:19092 (0)
[2025-08-04T21:50:44.972+0000] {conn.py:945} ERROR - <BrokerConnection client_id=kafka-python-producer-1, node_id=5 host=kafka-broker-2:19092 <connecting> [unspecified None]>: Closing connection. KafkaConnectionError: DNS failure
[2025-08-04T21:50:44.972+0000] {client_async.py:388} WARNING - Node 5 connection failed -- refreshing metadata
[2025-08-04T21:50:45.176+0000] {conn.py:1516} WARNING - DNS lookup failed for kafka-broker-3:19092, exception was [Errno -2] Name or service not known. Is your advertised.listeners (called advertised.host.name before Kafka 9) correct and resolvable?
[2025-08-04T21:50:45.176+0000] {conn.py:323} ERROR - <BrokerConnection client_id=kafka-python-producer-1, node_id=6 host=kafka-broker-3:19092 <connecting> [unspecified None]>: DNS lookup failed for kafka-broker-3:19092 (0)
[2025-08-04T21:50:45.177+0000] {conn.py:945} ERROR - <BrokerConnection client_id=kafka-python-producer-1, node_id=6 host=kafka-broker-3:19092 <connecting> [unspecified None]>: Closing connection. KafkaConnectionError: DNS failure
[2025-08-04T21:50:45.178+0000] {client_async.py:388} WARNING - Node 6 connection failed -- refreshing metadata
[2025-08-04T21:50:45.646+0000] {conn.py:1516} WARNING - DNS lookup failed for kafka-broker-1:19092, exception was [Errno -2] Name or service not known. Is your advertised.listeners (called advertised.host.name before Kafka 9) correct and resolvable?
[2025-08-04T21:50:45.647+0000] {conn.py:323} ERROR - <BrokerConnection client_id=kafka-python-producer-1, node_id=4 host=kafka-broker-1:19092 <connecting> [IPv4 ('172.18.0.9', 19092)]>: DNS lookup failed for kafka-broker-1:19092 (0)
[2025-08-04T21:50:45.647+0000] {conn.py:945} ERROR - <BrokerConnection client_id=kafka-python-producer-1, node_id=4 host=kafka-broker-1:19092 <connecting> [IPv4 ('172.18.0.9', 19092)]>: Closing connection. KafkaConnectionError: DNS failure
[2025-08-04T21:50:45.647+0000] {client_async.py:388} WARNING - Node 4 connection failed -- refreshing metadata
[2025-08-04T21:50:51.159+0000] {conn.py:1516} WARNING - DNS lookup failed for kafka-broker-1:19092, exception was [Errno -2] Name or service not known. Is your advertised.listeners (called advertised.host.name before Kafka 9) correct and resolvable?
[2025-08-04T21:50:51.160+0000] {conn.py:323} ERROR - <BrokerConnection client_id=kafka-python-producer-1, node_id=4 host=kafka-broker-1:19092 <connecting> [IPv4 ('172.18.0.9', 19092)]>: DNS lookup failed for kafka-broker-1:19092 (0)
[2025-08-04T21:50:51.160+0000] {conn.py:945} ERROR - <BrokerConnection client_id=kafka-python-producer-1, node_id=4 host=kafka-broker-1:19092 <connecting> [IPv4 ('172.18.0.9', 19092)]>: Closing connection. KafkaConnectionError: DNS failure
[2025-08-04T21:50:51.161+0000] {client_async.py:388} WARNING - Node 4 connection failed -- refreshing metadata
[2025-08-04T21:50:51.403+0000] {conn.py:1516} WARNING - DNS lookup failed for kafka-broker-2:19092, exception was [Errno -2] Name or service not known. Is your advertised.listeners (called advertised.host.name before Kafka 9) correct and resolvable?
[2025-08-04T21:50:51.403+0000] {conn.py:323} ERROR - <BrokerConnection client_id=kafka-python-producer-1, node_id=5 host=kafka-broker-2:19092 <connecting> [unspecified None]>: DNS lookup failed for kafka-broker-2:19092 (0)
[2025-08-04T21:50:51.404+0000] {conn.py:945} ERROR - <BrokerConnection client_id=kafka-python-producer-1, node_id=5 host=kafka-broker-2:19092 <connecting> [unspecified None]>: Closing connection. KafkaConnectionError: DNS failure
[2025-08-04T21:50:51.404+0000] {client_async.py:388} WARNING - Node 5 connection failed -- refreshing metadata
[2025-08-04T21:50:52.391+0000] {conn.py:1516} WARNING - DNS lookup failed for kafka-broker-3:19092, exception was [Errno -2] Name or service not known. Is your advertised.listeners (called advertised.host.name before Kafka 9) correct and resolvable?
[2025-08-04T21:50:52.392+0000] {conn.py:323} ERROR - <BrokerConnection client_id=kafka-python-producer-1, node_id=6 host=kafka-broker-3:19092 <connecting> [unspecified None]>: DNS lookup failed for kafka-broker-3:19092 (0)
[2025-08-04T21:50:52.392+0000] {conn.py:945} ERROR - <BrokerConnection client_id=kafka-python-producer-1, node_id=6 host=kafka-broker-3:19092 <connecting> [unspecified None]>: Closing connection. KafkaConnectionError: DNS failure
[2025-08-04T21:50:52.392+0000] {client_async.py:388} WARNING - Node 6 connection failed -- refreshing metadata
[2025-08-04T21:51:02.783+0000] {conn.py:1516} WARNING - DNS lookup failed for kafka-broker-2:19092, exception was [Errno -2] Name or service not known. Is your advertised.listeners (called advertised.host.name before Kafka 9) correct and resolvable?
[2025-08-04T21:51:02.784+0000] {conn.py:323} ERROR - <BrokerConnection client_id=kafka-python-producer-1, node_id=5 host=kafka-broker-2:19092 <connecting> [unspecified None]>: DNS lookup failed for kafka-broker-2:19092 (0)
[2025-08-04T21:51:02.784+0000] {conn.py:945} ERROR - <BrokerConnection client_id=kafka-python-producer-1, node_id=5 host=kafka-broker-2:19092 <connecting> [unspecified None]>: Closing connection. KafkaConnectionError: DNS failure
[2025-08-04T21:51:02.785+0000] {client_async.py:388} WARNING - Node 5 connection failed -- refreshing metadata
[2025-08-04T21:51:04.708+0000] {conn.py:1516} WARNING - DNS lookup failed for kafka-broker-3:19092, exception was [Errno -2] Name or service not known. Is your advertised.listeners (called advertised.host.name before Kafka 9) correct and resolvable?
[2025-08-04T21:51:04.709+0000] {conn.py:323} ERROR - <BrokerConnection client_id=kafka-python-producer-1, node_id=6 host=kafka-broker-3:19092 <connecting> [unspecified None]>: DNS lookup failed for kafka-broker-3:19092 (0)
[2025-08-04T21:51:04.709+0000] {conn.py:945} ERROR - <BrokerConnection client_id=kafka-python-producer-1, node_id=6 host=kafka-broker-3:19092 <connecting> [unspecified None]>: Closing connection. KafkaConnectionError: DNS failure
[2025-08-04T21:51:04.709+0000] {client_async.py:388} WARNING - Node 6 connection failed -- refreshing metadata
[2025-08-04T21:51:04.957+0000] {conn.py:1516} WARNING - DNS lookup failed for kafka-broker-1:19092, exception was [Errno -2] Name or service not known. Is your advertised.listeners (called advertised.host.name before Kafka 9) correct and resolvable?
[2025-08-04T21:51:04.957+0000] {conn.py:323} ERROR - <BrokerConnection client_id=kafka-python-producer-1, node_id=4 host=kafka-broker-1:19092 <connecting> [IPv4 ('172.18.0.9', 19092)]>: DNS lookup failed for kafka-broker-1:19092 (0)
[2025-08-04T21:51:04.958+0000] {conn.py:945} ERROR - <BrokerConnection client_id=kafka-python-producer-1, node_id=4 host=kafka-broker-1:19092 <connecting> [IPv4 ('172.18.0.9', 19092)]>: Closing connection. KafkaConnectionError: DNS failure
[2025-08-04T21:51:04.958+0000] {client_async.py:388} WARNING - Node 4 connection failed -- refreshing metadata
[2025-08-04T21:51:24.141+0000] {conn.py:1516} WARNING - DNS lookup failed for kafka-broker-2:19092, exception was [Errno -2] Name or service not known. Is your advertised.listeners (called advertised.host.name before Kafka 9) correct and resolvable?
[2025-08-04T21:51:24.142+0000] {conn.py:323} ERROR - <BrokerConnection client_id=kafka-python-producer-1, node_id=5 host=kafka-broker-2:19092 <connecting> [unspecified None]>: DNS lookup failed for kafka-broker-2:19092 (0)
[2025-08-04T21:51:24.142+0000] {conn.py:945} ERROR - <BrokerConnection client_id=kafka-python-producer-1, node_id=5 host=kafka-broker-2:19092 <connecting> [unspecified None]>: Closing connection. KafkaConnectionError: DNS failure
[2025-08-04T21:51:24.142+0000] {client_async.py:388} WARNING - Node 5 connection failed -- refreshing metadata
[2025-08-04T21:51:25.472+0000] {conn.py:1516} WARNING - DNS lookup failed for kafka-broker-3:19092, exception was [Errno -2] Name or service not known. Is your advertised.listeners (called advertised.host.name before Kafka 9) correct and resolvable?
[2025-08-04T21:51:25.473+0000] {conn.py:323} ERROR - <BrokerConnection client_id=kafka-python-producer-1, node_id=6 host=kafka-broker-3:19092 <connecting> [unspecified None]>: DNS lookup failed for kafka-broker-3:19092 (0)
[2025-08-04T21:51:25.473+0000] {conn.py:945} ERROR - <BrokerConnection client_id=kafka-python-producer-1, node_id=6 host=kafka-broker-3:19092 <connecting> [unspecified None]>: Closing connection. KafkaConnectionError: DNS failure
[2025-08-04T21:51:25.474+0000] {client_async.py:388} WARNING - Node 6 connection failed -- refreshing metadata
[2025-08-04T21:51:29.620+0000] {conn.py:1516} WARNING - DNS lookup failed for kafka-broker-1:19092, exception was [Errno -2] Name or service not known. Is your advertised.listeners (called advertised.host.name before Kafka 9) correct and resolvable?
[2025-08-04T21:51:29.621+0000] {conn.py:323} ERROR - <BrokerConnection client_id=kafka-python-producer-1, node_id=4 host=kafka-broker-1:19092 <connecting> [IPv4 ('172.18.0.9', 19092)]>: DNS lookup failed for kafka-broker-1:19092 (0)
[2025-08-04T21:51:29.621+0000] {conn.py:945} ERROR - <BrokerConnection client_id=kafka-python-producer-1, node_id=4 host=kafka-broker-1:19092 <connecting> [IPv4 ('172.18.0.9', 19092)]>: Closing connection. KafkaConnectionError: DNS failure
[2025-08-04T21:51:29.622+0000] {client_async.py:388} WARNING - Node 4 connection failed -- refreshing metadata
[2025-08-04T21:51:36.662+0000] {taskinstance.py:3313} ERROR - Task failed with exception
Traceback (most recent call last):
  File "/home/airflow/.local/lib/python3.12/site-packages/airflow/models/taskinstance.py", line 768, in _execute_task
    result = _execute_callable(context=context, **execute_callable_kwargs)
             ^^^^^^^^^^^^^^^^^^^^^^^^^^^^^^^^^^^^^^^^^^^^^^^^^^^^^^^^^^^^^
  File "/home/airflow/.local/lib/python3.12/site-packages/airflow/models/taskinstance.py", line 734, in _execute_callable
    return ExecutionCallableRunner(
           ^^^^^^^^^^^^^^^^^^^^^^^^
  File "/home/airflow/.local/lib/python3.12/site-packages/airflow/utils/operator_helpers.py", line 252, in run
    return self.func(*args, **kwargs)
           ^^^^^^^^^^^^^^^^^^^^^^^^^^
  File "/home/airflow/.local/lib/python3.12/site-packages/airflow/models/baseoperator.py", line 424, in wrapper
    return func(self, *args, **kwargs)
           ^^^^^^^^^^^^^^^^^^^^^^^^^^^
  File "/opt/airflow/plugins/artist_kafka_operator.py", line 47, in execute
    producer.send(self.kafka_topic, value=transaction)
  File "/home/airflow/.local/lib/python3.12/site-packages/kafka/producer/kafka.py", line 840, in send
    self._wait_on_metadata(topic, timer.timeout_ms)
  File "/home/airflow/.local/lib/python3.12/site-packages/kafka/producer/kafka.py", line 964, in _wait_on_metadata
    raise Errors.KafkaTimeoutError(
kafka.errors.KafkaTimeoutError: KafkaTimeoutError: Failed to update metadata after 60.0 secs.
[2025-08-04T21:51:36.680+0000] {taskinstance.py:1226} INFO - Marking task as FAILED. dag_id=artist_generator, task_id=generator_artist_data, run_id=scheduled__2025-01-08T00:00:00+00:00, execution_date=20250108T000000, start_date=20250804T215036, end_date=20250804T215136
[2025-08-04T21:51:36.694+0000] {taskinstance.py:341} INFO - ::group::Post task execution logs
[2025-08-04T21:51:36.695+0000] {standard_task_runner.py:124} ERROR - Failed to execute job 239 for task generator_artist_data (KafkaTimeoutError: Failed to update metadata after 60.0 secs.; 7228)
Traceback (most recent call last):
  File "/home/airflow/.local/lib/python3.12/site-packages/airflow/task/task_runner/standard_task_runner.py", line 117, in _start_by_fork
    ret = args.func(args, dag=self.dag)
          ^^^^^^^^^^^^^^^^^^^^^^^^^^^^^
  File "/home/airflow/.local/lib/python3.12/site-packages/airflow/cli/cli_config.py", line 49, in command
    return func(*args, **kwargs)
           ^^^^^^^^^^^^^^^^^^^^^
  File "/home/airflow/.local/lib/python3.12/site-packages/airflow/utils/cli.py", line 116, in wrapper
    return f(*args, **kwargs)
           ^^^^^^^^^^^^^^^^^^
  File "/home/airflow/.local/lib/python3.12/site-packages/airflow/cli/commands/task_command.py", line 483, in task_run
    task_return_code = _run_task_by_selected_method(args, _dag, ti)
                       ^^^^^^^^^^^^^^^^^^^^^^^^^^^^^^^^^^^^^^^^^^^^
  File "/home/airflow/.local/lib/python3.12/site-packages/airflow/cli/commands/task_command.py", line 256, in _run_task_by_selected_method
    return _run_raw_task(args, ti)
           ^^^^^^^^^^^^^^^^^^^^^^^
  File "/home/airflow/.local/lib/python3.12/site-packages/airflow/cli/commands/task_command.py", line 341, in _run_raw_task
    return ti._run_raw_task(
           ^^^^^^^^^^^^^^^^^
  File "/home/airflow/.local/lib/python3.12/site-packages/airflow/utils/session.py", line 97, in wrapper
    return func(*args, session=session, **kwargs)
           ^^^^^^^^^^^^^^^^^^^^^^^^^^^^^^^^^^^^^^
  File "/home/airflow/.local/lib/python3.12/site-packages/airflow/models/taskinstance.py", line 3006, in _run_raw_task
    return _run_raw_task(
           ^^^^^^^^^^^^^^
  File "/home/airflow/.local/lib/python3.12/site-packages/airflow/models/taskinstance.py", line 274, in _run_raw_task
    TaskInstance._execute_task_with_callbacks(
  File "/home/airflow/.local/lib/python3.12/site-packages/airflow/models/taskinstance.py", line 3161, in _execute_task_with_callbacks
    result = self._execute_task(context, task_orig)
             ^^^^^^^^^^^^^^^^^^^^^^^^^^^^^^^^^^^^^^
  File "/home/airflow/.local/lib/python3.12/site-packages/airflow/models/taskinstance.py", line 3185, in _execute_task
    return _execute_task(self, context, task_orig)
           ^^^^^^^^^^^^^^^^^^^^^^^^^^^^^^^^^^^^^^^
  File "/home/airflow/.local/lib/python3.12/site-packages/airflow/models/taskinstance.py", line 768, in _execute_task
    result = _execute_callable(context=context, **execute_callable_kwargs)
             ^^^^^^^^^^^^^^^^^^^^^^^^^^^^^^^^^^^^^^^^^^^^^^^^^^^^^^^^^^^^^
  File "/home/airflow/.local/lib/python3.12/site-packages/airflow/models/taskinstance.py", line 734, in _execute_callable
    return ExecutionCallableRunner(
           ^^^^^^^^^^^^^^^^^^^^^^^^
  File "/home/airflow/.local/lib/python3.12/site-packages/airflow/utils/operator_helpers.py", line 252, in run
    return self.func(*args, **kwargs)
           ^^^^^^^^^^^^^^^^^^^^^^^^^^
  File "/home/airflow/.local/lib/python3.12/site-packages/airflow/models/baseoperator.py", line 424, in wrapper
    return func(self, *args, **kwargs)
           ^^^^^^^^^^^^^^^^^^^^^^^^^^^
  File "/opt/airflow/plugins/artist_kafka_operator.py", line 47, in execute
    producer.send(self.kafka_topic, value=transaction)
  File "/home/airflow/.local/lib/python3.12/site-packages/kafka/producer/kafka.py", line 840, in send
    self._wait_on_metadata(topic, timer.timeout_ms)
  File "/home/airflow/.local/lib/python3.12/site-packages/kafka/producer/kafka.py", line 964, in _wait_on_metadata
    raise Errors.KafkaTimeoutError(
kafka.errors.KafkaTimeoutError: KafkaTimeoutError: Failed to update metadata after 60.0 secs.
[2025-08-04T21:51:36.718+0000] {local_task_job_runner.py:266} INFO - Task exited with return code 1
[2025-08-04T21:51:36.739+0000] {taskinstance.py:3901} INFO - 0 downstream tasks scheduled from follow-on schedule check
[2025-08-04T21:51:36.741+0000] {local_task_job_runner.py:245} INFO - ::endgroup::
